Workbook

Sheet Scoring Register
A1: Response ID | B1: Question ID | C1: Model | D1: Category | E1: Difficulty | F1: Prompt Used | G1: Complete Response | H1: Final Answer (0–2) | I1: Reasoning Quality (0–2) | J1: Instruction Following (0–2) | K1: Factual Support (0–2) | L1: Total Score (0–8) | M1: Date & Start Time | N1: Total Duration (s) | O1: Generation Duration (s) | P1: Output Tokens | Q1: Tokens/sec | R1: Peak VRAM (GB) | S1: Completion Status | T1: Verification Status | U1: Evidence Reference | V1: Evaluator Notes
A2: Q01_PHI | B2: Q01 | C2: phi4-mini-reasoning | D2: Mathematical reasoning | E2: Easy | F2: ='Question Bank & Key'!D3 -> Solve for x: 3x + 12 = 30. Show each step of your calculation clearly and state the final numerical value of x. | G2: [FINAL ANSWER] To solve the equation \(3x + 12 = 30\) for \(x\): 1. **Subtract 12 from both sides** to isolate the term with \(x\): \[ 3x + 12 - 12 = 30 - 12 \] Simplifying: \[ 3x = 18 \] 2. **Divide both sides by 3** to solve for \(x\): \[ \frac{3x}{3} = \frac{18}{3} \] Simplifying: \[ x = 6 \] **Verification**: Substitute \(x = 6\) back into the original equation: \[ 3(6) + 12 = 18 + 12 = 30 \] The left side equals the right side, confirming the solution is correct. **Final numerical value of \(x\)**: \(\boxed{6}\) [THINKING PROCESS (<think>)] Okay, so I need to solve the equation 3x + 12 = 30 for x. Let me think about how to approach this step by step. Alright, first, I remember that to solve for a variable like x, I need to isolate it on one side of the equation. That means getting rid of the constants and the coefficient that is multiplied by x. The equation here is 3x plus 12 equals 30. So, 3x + 12 = 30. The first thing I should do is try to get rid of that 12 that's being added to 3x. To do that, I can subtract 12 from both sides of the equation. That way, I maintain the equality because whatever I do to one side, I do to the other. So subtracting 12 from both sides makes sense. Let me write that down: 3x + 12 - 12 = 30 - 12. Simplifying both sides, the +12 and -12 on the left side cancel each other out, leaving just 3x. On the right side, 30 minus 12 is 18. So now the equation is 3x = 18. Okay, now I need to solve for x, which is multiplied by 3. To get x by itself, I should divide both sides of the equation by 3. That will undo the multiplication by 3. So dividing both sides by 3: 3x divided by 3 is x, and 18 divided by 3 is 6. Therefore, x equals 6. Wait, let me check my steps again to make sure I didn't make a mistake. Starting with the original equation: 3x +12 =30. Subtract 12 from both sides: 3x = 18. Then divide by 3: x=6. That seems right. Maybe I can plug the value back into the original equation to verify. Plugging x=6 into the left side: 3*(6) +12 = 18 +12 =30, which matches the right side of the equation. So that checks out. Hmm, yeah, that makes sense. So the solution is x=6. I think that's correct. No steps seem to be missing, and the arithmetic is straightforward. Yeah, I'm confident that's the right answer. | L2: =IF(COUNT(H2:K2)>0, SUM(H2:K2), "") | M2: 2026-09-16 11:49:08 | N2: 25.466 | O2: 18.619 | P2: 700 | Q2: =IF(AND(ISNUMBER(O2), O2>0, ISNUMBER(P2)), ROUND(P2/O2, 2), IF(AND(ISNUMBER(N2), N2>0, ISNUMBER(P2)), ROUND(P2/N2, 2), "")) -> 37.6 | R2: 3.64 | S2: Completed | T2: Pending | U2: data/responses/Q01_PHI.json
A3: Q01_DSR1 | B3: Q01 | C3: deepseek-r1:7b | D3: Mathematical reasoning | E3: Easy | F3: ='Question Bank & Key'!D3 -> Solve for x: 3x + 12 = 30. Show each step of your calculation clearly and state the final numerical value of x. | G3: [FINAL ANSWER] To solve the equation \( 3x + 12 = 30 \) for \( x \), follow these steps: 1. **Subtract 12 from both sides** to isolate the term with \( x \): \[ 3x + 12 - 12 = 30 - 12 \] Simplifying: \[ 3x = 18 \] 2. **Divide both sides by 3** to solve for \( x \): \[ \frac{3x}{3} = \frac{18}{3} \] Simplifying: \[ x = 6 \] **Final Answer:** \[ \boxed{6} \] [THINKING PROCESS (<think>)] First, I need to solve the equation 3x + 12 = 30 for x. I'll start by isolating the term with x. To do this, I'll subtract 12 from both sides of the equation. This simplifies the equation to 3x = 18. Next, I'll solve for x by dividing both sides by 3. Finally, I find that x equals 6. | L3: =IF(COUNT(H3:K3)>0, SUM(H3:K3), "") | M3: 2026-09-16 11:43:48 | N3: 18.13 | O3: 10.423 | P3: 260 | Q3: =IF(AND(ISNUMBER(O3), O3>0, ISNUMBER(P3)), ROUND(P3/O3, 2), IF(AND(ISNUMBER(N3), N3>0, ISNUMBER(P3)), ROUND(P3/N3, 2), "")) -> 24.94 | R3: 4.53 | S3: Completed | T3: Pending | U3: data/responses/Q01_DSR1.json
A4: Q01_QWEN | B4: Q01 | C4: qwen3:8b | D4: Mathematical reasoning | E4: Easy | F4: ='Question Bank & Key'!D3 -> Solve for x: 3x + 12 = 30. Show each step of your calculation clearly and state the final numerical value of x. | G4: [FINAL ANSWER] To solve the equation $ 3x + 12 = 30 $, we aim to isolate the variable $ x $ step by step. --- ### **Step 1: Subtract 12 from both sides** We begin by eliminating the constant term on the left-hand side. To do this, subtract 12 from both sides of the equation: $$ 3x + 12 - 12 = 30 - 12 $$ Simplifying both sides: $$ 3x = 18 $$ --- ### **Step 2: Divide both sides by 3** Now, to isolate $ x $, divide both sides of the equation by 3: $$ \frac{3x}{3} = \frac{18}{3} $$ Simplifying: $$ x = 6 $$ --- ### **Final Answer** $$ \boxed{6} $$ [THINKING PROCESS (<think>)] Okay, so I need to solve the equation 3x + 12 = 30 for x. Let me think about how to approach this. I remember that solving an equation like this usually involves isolating the variable, which in this case is x. First, I should get rid of that constant term on the left side, which is +12. To do that, I can subtract 12 from both sides of the equation. That way, I keep the equation balanced. Let me write that down: 3x + 12 - 12 = 30 - 12 Simplifying both sides, the +12 and -12 on the left side cancel each other out, leaving just 3x. On the right side, 30 minus 12 is 18. So now the equation is: 3x = 18 Alright, now I need to get x by itself. Since 3 is multiplied by x, I should divide both sides by 3 to undo that multiplication. Let me do that step: 3x / 3 = 18 / 3 Simplifying again, the 3's on the left side cancel out, leaving just x. On the right side, 18 divided by 3 is 6. So that gives me: x = 6 Wait, let me check if that makes sense. If I plug x = 6 back into the original equation, does it hold true? Original equation: 3x + 12 = 30 Substitute x with 6: 3*(6) + 12 = 18 + 12 = 30. Yep, that equals 30, which matches the right side of the equation. So it looks like x = 6 is the correct solution. Hmm, did I miss any steps? Let me go through it again. Starting with 3x + 12 = 30. Subtract 12 from both sides: 3x = 18. Divide by 3: x = 6. Yep, that seems straightforward. I don't think I made any mistakes here. The key steps were subtracting 12 first and then dividing by 3. It's important to perform the same operation on both sides to maintain equality. Another way to think about it might be to first divide all terms by 3, but that might complicate things because of the +12. Let me try that approach just to verify. If I divide every term by 3: (3x)/3 + 12/3 = 30/3 Which simplifies to x + 4 = 10. Then subtract 4 from both sides: x = 10 - 4 = 6. Oh, that works too! So whether I subtract first or divide first, I still end up with x = 6. That gives me more confidence that the answer is correct. So both methods lead to the same result. It's good to check using different methods to ensure consistency. I think that's all there is to it. The solution is x equals 6. | L4: =IF(COUNT(H4:K4)>0, SUM(H4:K4), "") | M4: 2026-09-16 11:36:45 | N4: 32.939 | O4: 28.401 | P4: 863 | Q4: =IF(AND(ISNUMBER(O4), O4>0, ISNUMBER(P4)), ROUND(P4/O4, 2), IF(AND(ISNUMBER(N4), N4>0, ISNUMBER(P4)), ROUND(P4/N4, 2), "")) -> 30.39 | R4: 5.35 | S4: Completed | T4: Pending | U4: data/responses/Q01_QWEN.json
A5: Q02_PHI | B5: Q02 | C5: phi4-mini-reasoning | D5: Mathematical reasoning | E5: Easy | F5: ='Question Bank & Key'!D4 -> A store offers a 20% discount on an item originally priced at $80. What is the final sale price? Show your work. | G5: [FINAL ANSWER] The original price of the item is $80. A 20% discount means you save 20% of $80, which is calculated as: \[ 80 \times 0.20 = 16 \] Subtracting this discount from the original price gives: \[ 80 - 16 = 64 \] Alternatively, the final price is \(80\% \times 80\): \[ 80 \times 0.80 = 64 \] **Final sale price:** \boxed{64} [THINKING PROCESS (<think>)] Okay, let's see. The problem is about calculating the final sale price of an item after a 20% discount. The original price is $80. Hmm, right. So, first, I need to figure out what 20% of $80 is, and then subtract that from the original price to get the sale price. Wait, percentage discounts... Yeah, so 20% off means you pay 80% of the original price, right? Or do you calculate the discount amount first and then subtract? Maybe both ways work. Let me think. Either way, the result should be the same. Let me try both methods to check. Method 1: Calculate the discount amount and subtract it from the original price. So, 20% of $80 is the discount. To find 20% of 80, I can convert 20% to a decimal, which is 0.20. Then multiply 80 by 0.20. Let me do that: 80 * 0.20. Hmm, 80 times 0.2 is 16. So the discount is $16. Then subtract that from $80: 80 - 16 = 64. So the sale price is $64. Method 2: If the discount is 20%, then the customer pays 80% of the original price. So, 80% of 80. Converting 80% to decimal is 0.80. Multiply 80 by 0.80: 80 * 0.80. Well, 80 times 0.8 is also 64. Same result. Okay, that checks out. Wait, just to make sure I didn't make a calculation mistake. Let me verify the multiplication again. 80 times 0.2: 0.2 is the same as 1/5. So 80 divided by 5 is 16. Yep, that's right. Then 80 minus 16 is 64. Correct. Alternatively, 0.8 times 80: 80 times 0.8. 8 times 8 is 64, so 80 times 0.8 is 64. Yep, that's consistent. So both methods lead to the same answer, $64. That seems right. I don't think I missed anything here. The problem is straightforward—a 20% discount on an $80 item. No additional taxes or fees mentioned, so the final sale price should be $64. | L5: =IF(COUNT(H5:K5)>0, SUM(H5:K5), "") | M5: 2026-09-16 11:49:55 | N5: 23.682 | O5: 17.302 | P5: 627 | Q5: =IF(AND(ISNUMBER(O5), O5>0, ISNUMBER(P5)), ROUND(P5/O5, 2), IF(AND(ISNUMBER(N5), N5>0, ISNUMBER(P5)), ROUND(P5/N5, 2), "")) -> 36.24 | R5: 3.64 | S5: Completed | T5: Pending | U5: data/responses/Q02_PHI.json
A6: Q02_DSR1 | B6: Q02 | C6: deepseek-r1:7b | D6: Mathematical reasoning | E6: Easy | F6: ='Question Bank & Key'!D4 -> A store offers a 20% discount on an item originally priced at $80. What is the final sale price? Show your work. | G6: [FINAL ANSWER] To determine the final sale price after applying a 20% discount to an item originally priced at \$80, follow these steps: 1. **Calculate the Discount Amount:** \[ \text{Discount} = \text{Original Price} \times \text{Discount Rate} = 80 \times 0.20 = 16 \] 2. **Subtract the Discount from the Original Price:** \[ \text{Final Sale Price} = \text{Original Price} - \text{Discount} = 80 - 16 = 64 \] **Final Answer:** \[ \boxed{64} \] [THINKING PROCESS (<think>)] First, I need to calculate the discount amount by finding 20% of the original price of $80. Next, I'll subtract the discount from the original price to determine the final sale price. | L6: =IF(COUNT(H6:K6)>0, SUM(H6:K6), "") | M6: 2026-09-16 11:44:32 | N6: 15.942 | O6: 8.493 | P6: 197 | Q6: =IF(AND(ISNUMBER(O6), O6>0, ISNUMBER(P6)), ROUND(P6/O6, 2), IF(AND(ISNUMBER(N6), N6>0, ISNUMBER(P6)), ROUND(P6/N6, 2), "")) -> 23.2 | R6: 4.53 | S6: Completed | T6: Pending | U6: data/responses/Q02_DSR1.json
A7: Q02_QWEN | B7: Q02 | C7: qwen3:8b | D7: Mathematical reasoning | E7: Easy | F7: ='Question Bank & Key'!D4 -> A store offers a 20% discount on an item originally priced at $80. What is the final sale price? Show your work. | G7: <think> Okay, let's see. The problem is about finding the final sale price of an item after a 20% discount. The original price is $80. Hmm, discounts can sometimes be tricky, but I think I can figure this out step by step. First, I need to remember how discounts work. A 20% discount means that the customer pays 80% of the original price, right? Because if you take away 20%, you're left with 100% - 20% = 80%. So instead of calculating the discount amount and subtracting it from the original price, maybe I can just calculate 80% of $80. Let me confirm that. Alternatively, I could calculate the discount amount first. Let me try both methods to check if they give the same result. That way, I can be sure I'm not making a mistake. Starting with the first method: calculating 80% of $80. To find 80% of something, I can convert the percentage to a decimal by dividing by 100. So 80% becomes 0.80. Then multiply that by the original price. So, 0.80 * $80. Let me do that multiplication. 0.8 times 80. Hmm, 0.8 is the same as 4/5, right? So 4/5 of 80. Well, 80 divided by 5 is 16, and 16 times 4 is 64. So that would be $64. Let me check with decimal multiplication. Alternatively, 80 * 0.8. Breaking it down: 80 * 0.8 is the same as 80 * 8 * 0.1. 80 * 8 is 640, and 640 * 0.1 is 64. Yep, same result. So that seems straightforward. Now, let me try the other method: calculating the discount amount first. A 20% discount on $80. So 20% of $80 is 0.20 * 80. Let me compute that. 0.2 times 80 is 16. So the discount is $16. Then subtract that from the original price: $80 - $16 = $64. Same answer. Okay, that's reassuring. Wait, just to make sure I didn't mix up any numbers. Let me verify once again. Original price is $80. 20% off. So 20% of 80 is indeed 16. Subtract 16 from 80, which gives 64. Alternatively, 80% of 80 is 64. Both methods lead to the same result. So the final sale price should be $64. Is there another way to think about this? Maybe using fractions? Let's see. 20% is 1/5. So 1/5 of 80 is 16, as before. Therefore, subtracting 1/5 from the original price, which is 80 - 16 = 64. Yep, same thing. Alternatively, if I wanted to use proportions. Let me try that. If 20% corresponds to $16, then 100% corresponds to $80. Wait, that's the original price. Maybe that's not helpful. Alternatively, setting up a proportion where the discount is 20% of the original price. So, discount amount / original price = 20% / 100%. Therefore, discount amount = (20/100)*80 = 16. Again, same result. I think all methods are converging to $64. Let me just check if there's any chance I made a calculation error. For example, if I thought 20% was 0.2, which it is, and 0.2 times 80 is 16. Yes. Then 80 minus 16 is 64. Alternatively, if I thought 20% was 0.2, and multiplied by 80, getting 16. So, no, that seems correct. Another way to think about percentages: 10% of 80 is 8, so 20% is double that, which is 16. Therefore, subtracting 16 from 80 gives 64. Yep, that works too. I think I've verified this multiple times using different methods: decimal multiplication, fraction conversion, proportion, and breaking down percentages into smaller parts. All of them lead to the same answer. Therefore, I can be confident that the final sale price after </think> | L7: =IF(COUNT(H7:K7)>0, SUM(H7:K7), "") | M7: 2026-09-16 11:39:17 | N7: 41.907 | O7: 33.498 | P7: 1024 | Q7: =IF(AND(ISNUMBER(O7), O7>0, ISNUMBER(P7)), ROUND(P7/O7, 2), IF(AND(ISNUMBER(N7), N7>0, ISNUMBER(P7)), ROUND(P7/N7, 2), "")) -> 30.57 | R7: 5.35 | S7: Completed | T7: Pending | U7: data/responses/Q02_QWEN.json | V7: Reached max tokens limit (num_predict=1024)
A8: Q03_PHI | B8: Q03 | C8: phi4-mini-reasoning | D8: Mathematical reasoning | E8: Medium | F8: ='Question Bank & Key'!D5 -> Calculate the total number of trailing zeroes in 100! (100 factorial). Explain the mathematical reasoning behind your method. | G8: [FINAL ANSWER] To calculate the total number of trailing zeroes in \(100!\) (100 factorial), we need to determine the number of times 10 is a factor in the factorial. Since 10 is the product of 2 and 5, [THINKING PROCESS (<think>)] Okay, so I need to figure out how many trailing zeros are in 100 factorial. Hmm, trailing zeros are the zeros at the end of the number right? Like, if the number ends with ...00, how many of those zeros are there? For example, 100 has two trailing zeros, right? But 100 factorial is a huge number. How do I even begin to calculate that? Wait, I remember something about factors contributing to trailing zeros. Since trailing zeros come from multiplying numbers that result in 10s, and 10 is 2 times 5. So each pair of 2 and 5 in the prime factors of 100! would contribute to a trailing zero. But there are usually more 2s than 5s in a factorial, so the number of trailing zeros should be determined by the number of 5s. Is that right? Let me check. For example, in 10!, the number of 5s would be 10/5 = 2, and the number of 2s would be 10/2 = 5, 10/4 = 5, 10/8 = 5, 10/6 = 1, etc. Wait, actually, the formula for counting the number of times a prime number p divides into n! is the sum of n divided by p, n divided by p squared, n divided by p cubed, and so on, until the division results in zero. So for 2s in 10!: 10/2 = 5, 10/4 = 2, 10/6 = 1, 10/8 = 1, 10/10 = 1. Adding those up: 5 + 2 + 1 + 0.5? Wait, no, it has to be integer division. So each time you divide n by p^k and take the floor. So for 10/2 = 5, 10/4 = 2 (since 10 divided by 4 is 2.5, floor to 2), 10/8 = 1, 10/16 = 0. So total 5 + 2 + 1 = 8. For 5s: 10/5 = 2, 10/25 = 0. So total 2. So trailing zeros would be 2. But 10! is 3628800, which has 2 trailing zeros. So that works. So the number of trailing zeros is the minimum of the number of 2s and 5s. Since 5s are less, we take the number of 5s. Therefore, for 100!, the number of trailing zeros is the number of times 5 is a factor in 100!. So how do we calculate the number of 5s in 100!? Using the formula: sum_{k=1 to infinity} floor(100 / 5^k) Compute each term: First term: floor(100 / 5) = floor(20) = 20 Second term: floor(100 / 25) = floor(4) = 4 Third term: floor(100 / 125) = floor(0.8) = 0 So higher powers will also result in zero. So total number of 5s is 20 + 4 = 24. Similarly, number of 2s would be more, but as we only need the minimum, which is 24. Therefore, the total number of trailing zeros in 100! is 24. Wait, let me verify this with a smaller factorial where I know the answer. Let's take 25!. Number of 5s: floor(25/5) = 5, floor(25/25) = 1, floor(25/125)=0. So total 6. Number of 2s: floor(25/2)=12, floor(25/4)=6, floor(25/8)=3, floor(25/16)=1, rest zero. Total 12+6+3+1=22. So trailing zeros should be 6. Let's check 25! value. 25! is 15511210043330985984000000. Wait, how many zeros is that? Let me count from the end: ...84000000. So starting from the end, 6 zeros. Yes, that's correct. So the method works. Therefore, applying the same logic to 100! gives 24 trailing zeros. So the answer should be 24. **Final Answer** The total number of trailing zeroes in 100! is \boxed{24}. | L8: =IF(COUNT(H8:K8)>0, SUM(H8:K8), "") | M8: 2026-09-16 11:50:51 | N8: 30.957 | O8: 26.738 | P8: 1024 | Q8: =IF(AND(ISNUMBER(O8), O8>0, ISNUMBER(P8)), ROUND(P8/O8, 2), IF(AND(ISNUMBER(N8), N8>0, ISNUMBER(P8)), ROUND(P8/N8, 2), "")) -> 38.3 | R8: 3.64 | S8: Completed | T8: Pending | U8: data/responses/Q03_PHI.json | V8: Reached max tokens limit (num_predict=1024)
A9: Q03_DSR1 | B9: Q03 | C9: deepseek-r1:7b | D9: Mathematical reasoning | E9: Medium | F9: ='Question Bank & Key'!D5 -> Calculate the total number of trailing zeroes in 100! (100 factorial). Explain the mathematical reasoning behind your method. | G9: <think> Okay, so I need to figure out how many trailing zeros are in 100 factorial, which is written as 100!. Hmm, I remember that trailing zeros are the zeros at the end of a number, right? Like, for example, 100! is a huge number, and it ends with several zeros. But how do I calculate exactly how many? I think it has something to do with how many times the number 10 is a factor in 100!. Because every time 10 is a factor, it adds a zero at the end. So, if I can find how many times 10 is a factor in 100!, that should give me the number of trailing zeros. But wait, 10 is 2 multiplied by 5, so maybe I need to find how many pairs of 2s and 5s are in the prime factors of 100!. But hold on, in any factorial, there are usually more 2s than 5s. So, the number of 5s will determine the number of trailing zeros. That makes sense because 2s are more common. So, I just need to count how many times 5 is a factor in the numbers from 1 to 100. How do I do that? I think it's by dividing 100 by 5 and then taking the floor of that result. Let me try that. 100 divided by 5 is 20. So, does that mean there are 20 trailing zeros? Wait, no, that can't be right because I remember that sometimes numbers like 25, 50, 75, and 100 contribute more than one 5. So, I need to account for those as well. Right, because 25 is 5 squared, so it contributes two 5s, and similarly, 50 is 5 times 10, which is 5 times 2 times 5, so that's two 5s as well. So, I need to not only divide by 5 but also divide by 25 to account for those extra 5s. So, let me calculate that. 100 divided by 5 is 20, and 100 divided by 25 is 4. So, adding those together, 20 plus 4 is 24. Hmm, so does that mean there are 24 trailing zeros? But wait, is that all? What about higher powers of 5, like 125? But 125 is greater than 100, so it won't contribute anything. So, I think 24 is the correct number. Let me verify this. So, in 100!, the number of 5s is the sum of 100 divided by 5, 100 divided by 25, 100 divided by 125, and so on. Since 125 is larger than 100, we can stop at 25. So, 100/5 is 20, 100/25 is 4, and 100/125 is 0. So, adding 20 and 4 gives 24. Therefore, there are 24 trailing zeros in 100!. But just to make sure I didn't make a mistake, let me think about a smaller factorial, like 25!. How many trailing zeros does that have? Using the same method, 25 divided by 5 is 5, and 25 divided by 25 is 1. So, 5 plus 1 is 6 trailing zeros. Let me check that. 25! is 15511210043330985984000000. Wait, actually, I think 25! has 6 trailing zeros. Yeah, that seems right. So, my method works for 25!. Another example: 50!. 50 divided by 5 is 10, 50 divided by 25 is 2, and 50 divided by 125 is 0. So, 10 plus 2 is 12 trailing zeros. Let me see, 50! is a huge number, but I think it does end with 12 zeros. So, that seems correct. Therefore, applying the same logic to 100!, it should have 24 trailing zeros. So, I think I can confidently say that the number of trailing zeros in 100! is 24. **Final Answer** The total number of trailing zeroes in 100! is \ </think> | L9: =IF(COUNT(H9:K9)>0, SUM(H9:K9), "") | M9: 2026-09-16 11:45:34 | N9: 36.115 | O9: 31.943 | P9: 1024 | Q9: =IF(AND(ISNUMBER(O9), O9>0, ISNUMBER(P9)), ROUND(P9/O9, 2), IF(AND(ISNUMBER(N9), N9>0, ISNUMBER(P9)), ROUND(P9/N9, 2), "")) -> 32.06 | R9: 4.53 | S9: Completed | T9: Pending | U9: data/responses/Q03_DSR1.json | V9: Reached max tokens limit (num_predict=1024)
A10: Q03_QWEN | B10: Q03 | C10: qwen3:8b | D10: Mathematical reasoning | E10: Medium | F10: ='Question Bank & Key'!D5 -> Calculate the total number of trailing zeroes in 100! (100 factorial). Explain the mathematical reasoning behind your method. | G10: <think> Okay, so I need to figure out how many trailing zeros are in 100 factorial, which is 100! Let me think about how to approach this. I remember that trailing zeros are created when a number is multiplied by 10, right? And since 10 is 2 times 5, each pair of 2 and 5 in the prime factors of 100! will contribute to a trailing zero. But wait, there are usually more 2s than 5s in the prime factors of a factorial. So the number of trailing zeros should depend on the number of 5s, because 5s are the limiting factor here. That makes sense because every even number contributes at least one 2, so there will be plenty of 2s to pair with the 5s. Therefore, I just need to count how many times 5 is a factor in the numbers from 1 to 100. But how exactly do I do that? Let me recall. I think the method involves dividing the number by 5, then by 25, 125, etc., until the division results in zero, and then adding up all those quotients. Let me try to remember why that works. So, for example, in 100!, the number of multiples of 5 between 1 and 100 is 100 divided by 5, which is 20. But some numbers contribute more than one 5. For instance, 25 is 5 squared, so it has two 5s. Similarly, 50, 75, and 100 are multiples of 25, each contributing an extra 5. Then there's 125, but 125 is greater than 100, so we stop there. Therefore, the total number of 5s is 20 (from the multiples of 5) plus 4 (from the multiples of 25) because 100 divided by 25 is 4. Wait, let me check that again. Let me write it down step by step. First, divide 100 by 5: 100 / 5 = 20. That counts all the multiples of 5. But numbers like 25, 50, 75, 100 are multiples of 25, and each of these has an additional 5. So we need to divide 100 by 25 to find how many numbers contribute an extra 5. 100 / 25 = 4. Then, numbers that are multiples of 125 would contribute yet another 5, but since 125 is 5 cubed, and 125 is greater than 100, there are no such numbers in 1 to 100. Therefore, we stop here. So adding those up: 20 + 4 = 24. Therefore, there are 24 trailing zeros in 100! Wait, let me verify this with another example to make sure I didn't make a mistake. Let's take a smaller factorial, like 25!. How many trailing zeros should it have? Using the same method: 25 / 5 = 5, 25 / 25 = 1, 25 / 125 = 0. So total is 5 + 1 = 6. Let me check 25! Well, 25! is 15511210043330985984000000. Let me count the trailing zeros. It ends with 6 zeros. Yes, that matches. So the method works here. Another example: 10! 10 / 5 = 2, 10 / 25 = 0. Total is 2. And 10! is 3628800, which has two trailing zeros. Correct. So going back to 100! The calculation is 100 / 5 = 20, 100 / 25 = 4, 100 / 125 = 0. So total is 20 + 4 = 24. Therefore, 24 trailing zeros. But let me think again why this method works. Essentially, every multiple of 5 contributes at least one 5, but multiples of higher powers of 5 contribute more. So by dividing by 5, 25, 125, etc., we account for all the 5s in the factorial. Since 2s are more plentiful, we don't </think> | L10: =IF(COUNT(H10:K10)>0, SUM(H10:K10), "") | M10: 2026-09-16 11:40:27 | N10: 41.31 | O10: 33.245 | P10: 1024 | Q10: =IF(AND(ISNUMBER(O10), O10>0, ISNUMBER(P10)), ROUND(P10/O10, 2), IF(AND(ISNUMBER(N10), N10>0, ISNUMBER(P10)), ROUND(P10/N10, 2), "")) -> 30.8 | R10: 5.35 | S10: Completed | T10: Pending | U10: data/responses/Q03_QWEN.json | V10: Reached max tokens limit (num_predict=1024)
A11: Q04_PHI | B11: Q04 | C11: phi4-mini-reasoning | D11: Mathematical reasoning | E11: Medium | F11: ='Question Bank & Key'!D6 -> Find the next two numbers in the sequence: 2, 6, 12, 20, 30, ... Explain the underlying rule governing the pattern. | G11: <think> Okay, let's see. The sequence given is 2, 6, 12, 20, 30, ... and I need to find the next two numbers. Hmm, let me start by looking at the differences between the numbers. That usually helps in spotting a pattern. So, starting with the first term: 2. The difference between 6 and 2 is 4. Then between 6 and 12, the difference is 6. Next, 12 to 20 is a difference of 8. Then 20 to 30, which is a difference of 10. Let me write down these differences: 6 - 2 = 4 12 - 6 = 6 20 - 12 = 8 30 - 20 = 10 So the differences between consecutive terms are 4, 6, 8, 10. Wait a minute, those differences themselves form a sequence. Let me check that sequence: 4, 6, 8, 10. That looks like it's increasing by 2 each time. So 4, then 4+2=6, then 6+2=8, then 8+2=10. If that pattern continues, the next difference should be 10 + 2 = 12, right? Then the difference after that would be 12 + 2 = 14. Let me verify that. The last difference was 10, leading to 30. So adding 12 to 30 would give 42. Then adding 14 to 42 would give 56. So the next two numbers should be 42 and 56. But let me make sure I'm not missing something here. Sometimes sequences can have more complex rules, so I should check another way. Alternatively, maybe the sequence is related to multiplying consecutive numbers. Let's see: 2 can be 1×2, 6 is 2×3, 12 is 3×4, 20 is 4×5, 30 is 5×6. Wait, that seems to fit. Let me check: 1×2 = 2 2×3 = 6 3×4 = 12 4×5 = 20 5×6 = 30 So the next term would be 6×7 = 42, and then 7×8 = 56. That matches the earlier result from the differences. So both methods point to 42 and 56. That seems solid. But let me check another angle just to be thorough. Another approach could be looking at the sequence in terms of primes or something else, but the numbers here are 2,6,12,20,30. Primes aren't really standing out here. 2 is prime, but 6 isn't, 12 isn't, etc. So probably not primes. How about factors? Each term is the product of two consecutive integers starting from 1×2. Yeah, that's the same as the earlier observation. Alternatively, maybe each term is n(n+1), where n starts at 1. Let's see: Term 1: 1×2 = 2 Term 2: 2×3 = 6 Term 3: 3×4 = 12 Term 4: 4×5 = 20 Term 5: 5×6 = 30 So term 6 would be 6×7=42, term 7=7×8=56. Yep, same result. Alternatively, maybe the sequence is related to adding numbers in some other way. Let's see, starting from 2, adding 4 gives 6, then adding 6 gives 12, adding 8 gives 20, adding 10 gives 30. So the added numbers are 4,6,8,10, which are even numbers starting from 4 increasing by 2 each time. So next addition is 12, then 14. So 30 +12=42, 42+14=56. Same answer. Is there another possible pattern? Let's see. Let's check the ratios between terms. 6/2=3, 12/6=2, 20/12≈1.666, 30/20=1.5. That doesn't seem to form a clear pattern. So ratios are probably not the way here. Alternatively, maybe the sequence is composite numbers with certain properties? But 2,6,12,20,30—those are all composite numbers, but that's too broad. The primes are 2, then composites. But the sequence includes 6, which is composite, 12, etc. But the primes are only the first term here. So probably not. Alternatively, maybe the sequence is n² + something. Let's check: Term 1: 1² +1=2 Term 2: 2² +2=6 Term 3: 3 | L11: =IF(COUNT(H11:K11)>0, SUM(H11:K11), "") | M11: 2026-09-16 11:52:11 | N11: 31.045 | O11: 26.793 | P11: 1024 | Q11: =IF(AND(ISNUMBER(O11), O11>0, ISNUMBER(P11)), ROUND(P11/O11, 2), IF(AND(ISNUMBER(N11), N11>0, ISNUMBER(P11)), ROUND(P11/N11, 2), "")) -> 38.22 | R11: 3.64 | S11: Completed | T11: Pending | U11: data/responses/Q04_PHI.json | V11: Reached max tokens limit (num_predict=1024)
A12: Q04_DSR1 | B12: Q04 | C12: deepseek-r1:7b | D12: Mathematical reasoning | E12: Medium | F12: ='Question Bank & Key'!D6 -> Find the next two numbers in the sequence: 2, 6, 12, 20, 30, ... Explain the underlying rule governing the pattern. | G12: [FINAL ANSWER] To determine the next two numbers in the sequence \(2, 6, 12, 20, 30, \ldots\), let's analyze the pattern governing the sequence. ### Step-by-Step Explanation: 1. **Identify the Pattern:** Let's list the given terms: \[ 2,\ 6,\ 12,\ 20,\ 30,\ \ldots \] To find the pattern, calculate the difference between consecutive terms: \[ \begin{align*} 6 - 2 &= 4 \\ 12 - 6 &= 6 \\ 20 - 12 &= 8 \\ 30 - 20 &= 10 \\ \end{align*} \] The differences between consecutive terms are \(4, 6, 8, 10\), which increase by \(2\) each time. 2. **Determine the Next Differences:** Following the observed pattern, the next differences should be: \[ 10 + 2 = 12 \\ 12 + 2 = 14 \\ \] 3. **Calculate the Next Terms:** Add these differences to the last term of the sequence: \[ \begin{align*} 30 + 12 &= 42 \\ 42 + 14 &= 56 \\ \end{align*} \] 4. **Conclusion:** The next two numbers in the sequence are: \[ \boxed{42,\ 56} \] [THINKING PROCESS (<think>)] To determine the next two numbers in the sequence 2, 6, 12, 20, 30, ..., I'll start by examining the differences between consecutive terms. First, I'll calculate the differences between each pair of adjacent numbers: 6 - 2 = 4 12 - 6 = 6 20 - 12 = 8 30 - 20 = 10 I notice that these differences are increasing by 2 each time: 4, 6, 8, 10. This suggests that the next difference should be 12, and the one after that should be 14. Now, to find the next two numbers in the sequence, I'll add these differences to the last known term: 30 + 12 = 42 42 + 14 = 56 Therefore, the next two numbers in the sequence are 42 and 56. | L12: =IF(COUNT(H12:K12)>0, SUM(H12:K12), "") | M12: 2026-09-16 11:46:39 | N12: 23.051 | O12: 18.898 | P12: 571 | Q12: =IF(AND(ISNUMBER(O12), O12>0, ISNUMBER(P12)), ROUND(P12/O12, 2), IF(AND(ISNUMBER(N12), N12>0, ISNUMBER(P12)), ROUND(P12/N12, 2), "")) -> 30.21 | R12: 4.53 | S12: Completed | T12: Pending | U12: data/responses/Q04_DSR1.json
A13: Q04_QWEN | B13: Q04 | C13: qwen3:8b | D13: Mathematical reasoning | E13: Medium | F13: ='Question Bank & Key'!D6 -> Find the next two numbers in the sequence: 2, 6, 12, 20, 30, ... Explain the underlying rule governing the pattern. | G13: <think> Okay, let's see. I need to find the next two numbers in the sequence: 2, 6, 12, 20, 30, ... and explain the rule. Hmm, let me start by looking at the differences between the numbers. First, let me write down the terms with their positions to see if that helps. Let's say the first term is term 1, second term is term 2, etc. Term 1: 2 Term 2: 6 Term 3: 12 Term 4: 20 Term 5: 30 Term 6: ? Term 7: ? Now, let me calculate the differences between consecutive terms. Term 2 - Term 1 = 6 - 2 = 4 Term 3 - Term 2 = 12 - 6 = 6 Term 4 - Term 3 = 20 - 12 = 8 Term 5 - Term 4 = 30 - 20 = 10 So the differences between the terms are 4, 6, 8, 10... That seems like an arithmetic sequence where each difference increases by 2. Let me check: First difference: 4 Second difference: 6 (which is 4 + 2) Third difference: 8 (which is 6 + 2) Fourth difference: 10 (which is 8 + 2) Yes, so the differences are increasing by 2 each time. If this pattern continues, the next difference should be 10 + 2 = 12. Therefore, Term 6 would be Term 5 + 12 = 30 + 12 = 42. Then the following difference would be 12 + 2 = 14, making Term 7 = 42 + 14 = 56. But let me verify if there's another way to look at this sequence. Sometimes sequences can be represented by formulas involving n, the term number. Let me check if there's a formula for the nth term. Looking at the terms: Term 1: 2 Term 2: 6 Term 3: 12 Term 4: 20 Term 5: 30 Hmm, these numbers look familiar. Let me think... 2 is 1×2, 6 is 2×3, 12 is 3×4, 20 is 4×5, 30 is 5×6. Oh! So each term is n multiplied by (n + 1), where n starts at 1. Let me check: For Term 1: 1×(1+1) = 1×2 = 2 ✔️ Term 2: 2×(2+1) = 2×3 = 6 ✔️ Term 3: 3×4 = 12 ✔️ Term 4: 4×5 = 20 ✔️ Term 5: 5×6 = 30 ✔️ Yes! So the general formula for the nth term is n(n + 1). Therefore, Term 6 would be 6×7 = 42, and Term 7 is 7×8 = 56. That matches the earlier result from the differences. So both methods lead to the same conclusion. The sequence is generated by multiplying each term's position by one more than the position. Therefore, the next two numbers are 42 and 56. Let me just make sure there isn't another possible pattern. For example, sometimes sequences can involve factorials or other operations, but in this case, the multiplication pattern seems straightforward. Let me check if the differences could also be explained by another rule. The differences are 4, 6, 8, 10,... which is an arithmetic progression with first term 4 and common difference 2. So the difference between term n and term n-1 is 4 + 2(n-2). Wait, let me think. Actually, the first difference (between term 1 and term 2) is 4. If we consider the difference between term k and term k-1 as 2k + 2? Wait, maybe not. Let me think again. Alternatively, since the nth term is n(n+1), then the difference between term n and term n-1 is: Term n - Term (n-1) = n(n + 1) - (n - 1)(n) = n² + n - [n(n - 1)] = n² + n - (n² - n) = n² + n - n² + n = </think> | L13: =IF(COUNT(H13:K13)>0, SUM(H13:K13), "") | M13: 2026-09-16 11:41:41 | N13: 37.544 | O13: 33.053 | P13: 1024 | Q13: =IF(AND(ISNUMBER(O13), O13>0, ISNUMBER(P13)), ROUND(P13/O13, 2), IF(AND(ISNUMBER(N13), N13>0, ISNUMBER(P13)), ROUND(P13/N13, 2), "")) -> 30.98 | R13: 5.35 | S13: Completed | T13: Pending | U13: data/responses/Q04_QWEN.json | V13: Reached max tokens limit (num_predict=1024)
A14: Q05_PHI | B14: Q05 | C14: phi4-mini-reasoning | D14: Mathematical reasoning | E14: Hard | F14: ='Question Bank & Key'!D7 -> Three fair standard six-sided dice are rolled simultaneously. What is the exact probability that the sum of the numbers rolled is equal to 10? Express your answer as a simplified fraction and explain each step. | G14: <think> Okay, so I need to find the probability that the sum of three six-sided dice is exactly 10. Let me think about how to approach this. First, I remember that when dealing with probabilities involving dice, it's often helpful to figure out the total number of possible outcomes and then the number of favorable outcomes. The probability would then be the ratio of favorable outcomes to total outcomes. Since there are three dice, each die has 6 possible outcomes. So the total number of possible outcomes should be 6 * 6 * 6. Let me calculate that: 6 * 6 is 36, and 36 * 6 is 216. So there are 216 possible outcomes when rolling three dice. That part seems straightforward. Now, the tricky part is figuring out how many of those outcomes result in a sum of 10. To do this, I need to count all the ordered triples (a, b, c) where each of a, b, c is between 1 and 6 inclusive, and a + b + c = 10. I recall that this is a problem of finding the number of integer solutions to the equation a + b + c = 10 with each variable at least 1 and at most 6. Since each die must show at least 1, the minimum sum is 3 (1+1+1) and the maximum is 18 (6+6+6). So 10 is within that range. To solve the equation a + b + c = 10 with 1 ≤ a, b, c ≤ 6, I can use the stars and bars method. But wait, stars and bars usually applies when variables are non-negative integers. Since each die must be at least 1, I can make a substitution: let a' = a - 1, b' = b - 1, c' = c - 1. Then the equation becomes a' + b' + c' = 10 - 3 = 7, where a', b', c' are non-negative integers and each a' ≤ 5, b' ≤ 5, c' ≤ 5 (since the original variables can't exceed 6). So now the problem is transformed into finding the number of non-negative integer solutions to a' + b' + c' = 7 with each variable at most 5. The standard stars and bars formula without restrictions would give C(7 + 3 - 1, 3 - 1) = C(9, 2) = 36 solutions. But this includes solutions where one or more variables exceed 5. So we need to subtract those cases where a variable is greater than 5. Let me recall the inclusion-exclusion principle here. The number of solutions where a' ≥ 6 (since the original variables can be at most 6, so a' = a - 1 ≤ 5). If a' ≥ 6, let’s set a'' = a' - 6. Then the equation becomes a'' + b' + c' = 7 - 6 = 1. The number of solutions here is C(1 + 3 - 1, 3 - 1) = C(3, 2) = 3. Similarly, the same applies if b' ≥ 6 or c' ≥ 6. So there are 3 * 3 = 9 such solutions where any one variable exceeds 5. But wait, inclusion-exclusion also requires considering cases where two variables exceed 5. However, if two variables exceed 5, say a' ≥ 6 and b' ≥ 6, then setting a'' = a' - 6 and b'' = b' - 6, the equation becomes a'' + b'' + c' = 7 - 12 = -5. Since the right-hand side is negative, there are no solutions here. Similarly, any two variables exceeding 5 would lead to a negative total, which isn't possible. So there are no such cases to add back in. Therefore, the number of valid solutions is total solutions without restrictions (36) minus the solutions where any variable exceeds 5 (9), giving 36 - 9 = 27. But wait, hold on. Let me verify this. So the original equation after substitution is a' + b' + c' = 7, with each a', b', c' ≤ 5. The number of solutions is C(9, 2) - 3*C(3, 2). Wait, no, inclusion-exclusion formula is: Number of solutions = total solutions - sum of solutions where each variable exceeds - sum of solutions where two variables exceed + ... But in this case, the number of solutions where a single variable exceeds 5 is 3 (as calculated earlier) for each variable, so 3 * 3 = 9. Since there are no | L14: =IF(COUNT(H14:K14)>0, SUM(H14:K14), "") | M14: 2026-09-16 11:53:17 | N14: 30.627 | O14: 26.364 | P14: 1024 | Q14: =IF(AND(ISNUMBER(O14), O14>0, ISNUMBER(P14)), ROUND(P14/O14, 2), IF(AND(ISNUMBER(N14), N14>0, ISNUMBER(P14)), ROUND(P14/N14, 2), "")) -> 38.84 | R14: 3.64 | S14: Completed | T14: Pending | U14: data/responses/Q05_PHI.json | V14: Reached max tokens limit (num_predict=1024)
A15: Q05_DSR1 | B15: Q05 | C15: deepseek-r1:7b | D15: Mathematical reasoning | E15: Hard | F15: ='Question Bank & Key'!D7 -> Three fair standard six-sided dice are rolled simultaneously. What is the exact probability that the sum of the numbers rolled is equal to 10? Express your answer as a simplified fraction and explain each step. | G15: <think> Okay, so I have this problem where I need to find the probability that the sum of three fair six-sided dice is equal to 10. Hmm, let me think about how to approach this. I remember that when dealing with probabilities involving dice, it's often useful to figure out the number of favorable outcomes divided by the total number of possible outcomes. First, let me recall that each die has 6 faces, so when rolling three dice, the total number of possible outcomes is 6 multiplied by itself three times, which is 6^3. Let me calculate that: 6*6 is 36, and 36*6 is 216. So, there are 216 possible outcomes when rolling three dice. Got that down. Now, the tricky part is figuring out how many of these outcomes result in a sum of 10. I think this is a combinatorics problem where I need to find the number of integer solutions to the equation a + b + c = 10, where each of a, b, and c is at least 1 and at most 6. Because each die can only show a number from 1 to 6, inclusive. Wait, so each die must be at least 1, so maybe I can adjust the equation to account for that. If I let a' = a - 1, b' = b - 1, c' = c - 1, then each of a', b', c' is at least 0. Then the equation becomes (a' + 1) + (b' + 1) + (c' + 1) = 10, which simplifies to a' + b' + c' = 7. So now, I need to find the number of non-negative integer solutions to a' + b' + c' = 7, where each a', b', c' is at most 5, because the original a, b, c can be at most 6, so a' = a - 1 can be at most 5. I remember that the formula for the number of non-negative integer solutions to x1 + x2 + ... + xn = k is C(k + n - 1, n - 1). So in this case, n is 3, k is 7, so the number of solutions without any restrictions would be C(7 + 3 - 1, 3 - 1) = C(9, 2). Let me compute that: 9 choose 2 is (9*8)/(2*1) = 36. So there are 36 solutions without considering the upper limit of 5 on each variable. But wait, some of these solutions might have a' > 5, which would mean a > 6, which isn't allowed. So I need to subtract those cases where one or more of a', b', c' exceed 5. This is where the inclusion-exclusion principle comes into play. First, I need to find the number of solutions where a' >= 6. If a' >= 6, let's set a'' = a' - 6, so a'' >= 0. Then the equation becomes a'' + b' + c' = 7 - 6 = 1. The number of non-negative solutions to this is C(1 + 3 - 1, 3 - 1) = C(3, 2) = 3. Similarly, the same number applies for b' >=6 and c' >=6. So each variable exceeding 5 contributes 3 solutions. But wait, can two variables exceed 5 at the same time? Let's check. If a' >=6 and b' >=6, then a'' = a' -6, b'' = b' -6, so the equation becomes a'' + b'' + c' = 7 - 12 = -5. That's not possible, so there are no solutions where two variables exceed 5. Therefore, we don't have to worry about overcounting in the inclusion-exclusion principle beyond subtracting the cases where one variable exceeds 5. So, the total number of invalid solutions is 3 variables * 3 solutions each = 9. Therefore, the number of valid solutions is 36 - 9 = 27. Wait, hold on. Let me verify that. So, the initial number of solutions is 36. Then, for each die, if it exceeds 5, we subtract 3. Since there are three dice, that's 3*3=9. So 36 - 9 = 27. That seems right. But just to make sure, maybe I can list all the possible combinations that sum to 10 with three dice. Let me see. Alternatively, maybe I can think of it as </think> | L15: =IF(COUNT(H15:K15)>0, SUM(H15:K15), "") | M15: 2026-09-16 11:47:50 | N15: 35.292 | O15: 31.119 | P15: 1024 | Q15: =IF(AND(ISNUMBER(O15), O15>0, ISNUMBER(P15)), ROUND(P15/O15, 2), IF(AND(ISNUMBER(N15), N15>0, ISNUMBER(P15)), ROUND(P15/N15, 2), "")) -> 32.91 | R15: 4.53 | S15: Completed | T15: Pending | U15: data/responses/Q05_DSR1.json | V15: Reached max tokens limit (num_predict=1024)
A16: Q05_QWEN | B16: Q05 | C16: qwen3:8b | D16: Mathematical reasoning | E16: Hard | F16: ='Question Bank & Key'!D7 -> Three fair standard six-sided dice are rolled simultaneously. What is the exact probability that the sum of the numbers rolled is equal to 10? Express your answer as a simplified fraction and explain each step. | G16: <think> Okay, so I need to find the probability that when rolling three standard six-sided dice, the sum is exactly 10. Let me think about how to approach this. First, I remember that when dealing with probabilities involving dice, it's often helpful to figure out the total number of possible outcomes and then determine how many of those outcomes result in the desired sum. Since each die has 6 sides, and we're rolling three dice, the total number of possible outcomes should be 6 multiplied by itself three times. Let me write that down: Total outcomes = 6 × 6 × 6 = 216. Okay, so there are 216 possible outcomes when rolling three dice. Now, I need to find how many of these outcomes result in a sum of 10. To do this, I think I need to find all the combinations of three numbers (each between 1 and 6) that add up to 10. Each number represents the result of one die. Let me denote the three numbers as a, b, and c, where each of them is an integer between 1 and 6 inclusive, and a + b + c = 10. So, the problem reduces to finding the number of integer solutions to the equation a + b + c = 10 with 1 ≤ a, b, c ≤ 6. But how do I count these solutions? I remember something about stars and bars from combinatorics, but I also need to consider the upper limits on each variable (since each die can't exceed 6). Let me recall. The standard stars and bars formula for the number of positive integer solutions to a + b + c = n is C(n-1, 2), where C is the combination function. However, this doesn't account for the upper limits on each variable. Since each die can only go up to 6, we need to adjust for that. Alternatively, maybe I can use generating functions? Or perhaps it's easier to list all possible combinations? Wait, listing might be tedious, but since the numbers are small, maybe manageable. Let me try both approaches and see which works better. First, let me try the stars and bars approach with inclusion-exclusion. The equation is a + b + c = 10, with 1 ≤ a, b, c ≤ 6. Let me first adjust the variables to make them non-negative integers. Let me set a' = a - 1, b' = b - 1, c' = c - 1. Then, the equation becomes: a' + 1 + b' + 1 + c' + 1 = 10 ⇒ a' + b' + c' = 10 - 3 = 7. Now, the problem is to find the number of non-negative integer solutions to a' + b' + c' = 7, where each a', b', c' ≤ 5 (since original variables a, b, c ≤ 6, so subtracting 1 gives ≤5). The standard number of solutions without considering the upper bounds is C(7 + 3 - 1, 3 - 1) = C(9, 2) = 36. But this counts solutions where some variables might exceed 5. So we need to subtract those cases where one or more variables are greater than 5. Let me recall inclusion-exclusion principle here. First, compute the total number of solutions without restrictions: C(9, 2) = 36. Now, subtract the number of solutions where at least one variable is ≥6. Let's compute that. Let me define A as the set of solutions where a' ≥ 6, B where b' ≥ 6, and C where c' ≥ 6. We need to compute |A ∪ B ∪ C| and subtract it from the total. By inclusion-exclusion: |A ∪ B ∪ C| = |A| + |B| + |C| - |A ∩ B| - |A ∩ C| - |B ∩ C| + |A ∩ B ∩ C|. First, compute |A|. If a' ≥ 6, let me set a'' = a' - 6 ≥ 0. Then the equation becomes a'' + 6 + b' + c' = 7 ⇒ a'' + b' + c' = 1. The number of non-negative solutions is C(1 + 3 - 1, 3 - 1) = C(3, 2) = 3. Similarly, |B| = |C| = 3. So total for |A| + |B| + |C| = 3*3 = 9. Next, compute |A ∩ B|. This is the number of solutions where </think> | L16: =IF(COUNT(H16:K16)>0, SUM(H16:K16), "") | M16: 2026-09-16 11:42:45 | N16: 37.811 | O16: 33.269 | P16: 1024 | Q16: =IF(AND(ISNUMBER(O16), O16>0, ISNUMBER(P16)), ROUND(P16/O16, 2), IF(AND(ISNUMBER(N16), N16>0, ISNUMBER(P16)), ROUND(P16/N16, 2), "")) -> 30.78 | R16: 5.35 | S16: Completed | T16: Pending | U16: data/responses/Q05_QWEN.json | V16: Reached max tokens limit (num_predict=1024)
A17: Q06_PHI | B17: Q06 | C17: phi4-mini-reasoning | D17: Logical reasoning | E17: Easy | F17: ='Question Bank & Key'!D8 -> A farmer has 17 sheep, and all but 9 die. How many live sheep does the farmer have left? State your answer and briefly explain the logic. | G17: [FINAL ANSWER] The farmer originally has 17 sheep. The phrase "all but 9 die" means that **9 sheep survive**, and the remaining **17 - 9 = 8** die. **Answer:** \boxed{9} *Logic:* "All but 9 die" implies 9 sheep do not die (survive), so the farmer has 9 live sheep left. [THINKING PROCESS (<think>)] Okay, let's see. The problem says a farmer has 17 sheep, and all but 9 die. How many live sheep does the farmer have left? Hmm. So, the farmer starts with 17 sheep. Then "all but 9 die." Wait, "all but 9" die. So, does that mean that except for 9 sheep, all die? Or does it mean that all die except for 9? Let me parse this sentence again. The phrase "all but 9 die" – "but" here is used to contrast. So, it's like saying "everyone except for 9 die," which would mean that 9 sheep do not die, and all the others die. So, if the farmer originally has 17 sheep, and all but 9 die, then 9 survive, and 17 minus 9 die. So, 17 - 9 = 8. Wait, no. Wait, if all but 9 die, then the number that die is total minus 9. So, 17 total sheep, all but 9 die, so 17 - 9 = 8 sheep die, and 9 survive. Therefore, the farmer has 9 live sheep left. But wait, let me make sure. Sometimes these problems can be tricky with the wording. Let's break it down. "All but 9 die" – "all" refers to the entire group except for 9. So, out of the 17 sheep, "all" would mean every sheep, but there's an exception: 9 that don't die. So, 9 sheep survive, and the remaining (17 - 9 = 8) die. Therefore, the answer should be 9. Alternatively, someone might misinterpret "all but 9 die" as "first, all die, but then 9 remain," but that doesn't make sense. The correct interpretation is that except for 9, all the sheep die. So, 8 die, 9 survive. So, the farmer has 9 live sheep left. Another way to think about it: "all but X" means "completely except for X." So, if you have all but X of something, that means you have X left and the rest are excluded. For example, if I say "all but one of the cookies were eaten," that means one cookie remains.Even more clearly, if the problem had said "all but 9 died," then the number of living sheep would be 9. Because "all but 9" refers to the dying ones, so 9 live. So, the key is understanding that "all but 9" die. So, the death toll is 17 - 9 = 8, and survivors are 9. Therefore, the answer is 9. | L17: =IF(COUNT(H17:K17)>0, SUM(H17:K17), "") | M17: 2026-09-16 11:59:00 | N17: 23.833 | O17: 16.919 | P17: 662 | Q17: =IF(AND(ISNUMBER(O17), O17>0, ISNUMBER(P17)), ROUND(P17/O17, 2), IF(AND(ISNUMBER(N17), N17>0, ISNUMBER(P17)), ROUND(P17/N17, 2), "")) -> 39.13 | R17: 3.64 | S17: Completed | T17: Pending | U17: data/responses/Q06_PHI.json
A18: Q06_DSR1 | B18: Q06 | C18: deepseek-r1:7b | D18: Logical reasoning | E18: Easy | F18: ='Question Bank & Key'!D8 -> A farmer has 17 sheep, and all but 9 die. How many live sheep does the farmer have left? State your answer and briefly explain the logic. | G18: [FINAL ANSWER] Sure, let's break down the problem step by step. **Problem Statement:** A farmer has 17 sheep, and all but 9 die. How many live sheep does the farmer have left? **Solution:** 1. **Initial Number of Sheep:** - The farmer starts with **17 sheep**. 2. **Understanding "All but 9 Die":** - The phrase "all but 9" means that **all sheep except 9** die. - In other words, **9 sheep survive**. 3. **Calculating the Number of Live Sheep:** - Total sheep initially = 17 - Sheep that die = 17 - 9 = 8 - Sheep that survive = 9 **Final Answer:** \[ \boxed{9} \] [THINKING PROCESS (<think>)] First, the farmer starts with 17 sheep. The phrase "all but 9 die" means that 9 sheep survive. Therefore, the number of live sheep remaining is 9. | L18: =IF(COUNT(H18:K18)>0, SUM(H18:K18), "") | M18: 2026-09-16 11:22:53 | N18: 13.25 | O18: 9.038 | P18: 217 | Q18: =IF(AND(ISNUMBER(O18), O18>0, ISNUMBER(P18)), ROUND(P18/O18, 2), IF(AND(ISNUMBER(N18), N18>0, ISNUMBER(P18)), ROUND(P18/N18, 2), "")) -> 24.01 | R18: 4.53 | S18: Completed | T18: Pending | U18: data/responses/Q06_DSR1.json
A19: Q06_QWEN | B19: Q06 | C19: qwen3:8b | D19: Logical reasoning | E19: Easy | F19: ='Question Bank & Key'!D8 -> A farmer has 17 sheep, and all but 9 die. How many live sheep does the farmer have left? State your answer and briefly explain the logic. | G19: [FINAL ANSWER] The farmer has **9 live sheep** left. **Explanation:** The phrase "all but 9 die" means that 9 sheep are exceptions to the action of dying. Therefore, out of the 17 sheep, 9 survive, and the remaining 8 die. The question specifically asks for the number of live sheep, which is the 9 that did not die. **Answer:** 9 live sheep. [THINKING PROCESS (<think>)] Okay, let's see. The problem says a farmer has 17 sheep, and all but 9 die. How many live sheep does the farmer have left? Hmm, so first, I need to understand what "all but 9 die" means. The phrase "all but 9" usually means that 9 are exceptions. So if there are 17 sheep total, and all except 9 die, that would mean 9 survive. Wait, but the question is asking how many live sheep are left. So if all but 9 die, then 9 are alive. But let me make sure I'm interpreting this correctly. Let me break it down. The farmer starts with 17 sheep. "All but 9 die" – so "all" refers to all the sheep, except for 9. So the number of sheep that die is total sheep minus the ones that don't die. So total sheep is 17. If all but 9 die, then the number that die is 17 - 9 = 8. Wait, that would mean 8 die and 9 are left? Wait, that seems conflicting. Let me think again. Wait, maybe I'm mixing up the phrasing. If "all but 9 die," that means that 9 are not dying, so they are the ones that survive. Therefore, the number of live sheep would be 9. But then the total number of sheep is 17, so 17 - 9 = 8 died. So the answer would be 9? But let me check if that's correct. Alternatively, sometimes people might misinterpret "all but 9" as meaning that 9 are left, so the answer is 9. But maybe there's a trick here. Let me think again. Suppose the farmer has 17 sheep. All but 9 die. So "all" refers to all the sheep, and "but 9" means that 9 are exceptions. Therefore, 9 are alive, and the rest (17 - 9 = 8) die. Therefore, the number of live sheep is 9. So the answer is 9. But wait, maybe there's a different way to interpret it. For example, if someone says "all but 9 die," does that mean that 9 die and the rest live? No, that would be different. "All but 9" would mean that 9 are not included in the "all." So if you have all except 9, then 9 are the ones that are not part of the "all." So if the "all" refers to the ones that die, then "all but 9" would mean that 9 are not dying, so they are alive. Therefore, the answer is 9. Alternatively, maybe the question is trying to trick you into thinking it's 8, but actually, it's 9. Let me check with an example. Suppose there are 10 sheep. If all but 3 die, how many live? It would be 3. So applying the same logic, 17 sheep, all but 9 die, so 9 live. Therefore, the answer is 9. But wait, maybe there's a trick with the wording. The question says "all but 9 die." So "all" refers to the entire group. So "all but 9" is the same as "9 are left." Therefore, the answer is 9. So the farmer has 9 live sheep left. That seems straightforward. But maybe I need to confirm with another example. If there are 5 sheep, and all but 2 die, then 2 are left. So yes, same logic. Therefore, in the original problem, 17 sheep, all but 9 die, so 9 are left. Therefore, the answer is 9. But wait, sometimes people might think that "all but 9" means that 9 die, but that would be incorrect. Because "all but 9" is a way of saying "everything except 9," so the 9 are the ones that are not included in the action. Since the action is "die," then the 9 are the ones that don't die. Therefore, the answer is 9. So I think that's the correct answer. | L19: =IF(COUNT(H19:K19)>0, SUM(H19:K19), "") | M19: 2026-09-16 11:30:23 | N19: 40.401 | O19: 31.734 | P19: 995 | Q19: =IF(AND(ISNUMBER(O19), O19>0, ISNUMBER(P19)), ROUND(P19/O19, 2), IF(AND(ISNUMBER(N19), N19>0, ISNUMBER(P19)), ROUND(P19/N19, 2), "")) -> 31.35 | R19: 5.35 | S19: Completed | T19: Pending | U19: data/responses/Q06_QWEN.json
